<?php


namespace Backoff;


use PHPUnit\Framework\TestCase;
use \RuntimeException;

class BackoffTest extends TestCase
{
    protected $calls;

    protected function setUp(): void
    {
        $this->calls = 1;
    }

    public function testCallWithOneAttempt() {
        $backoff = new Backoff();
        $backoff->setInterval(2);
        $backoff->setMaxAttempts(1);
        $this->expectException(\Exception::class);
        $backoff->call($this->retryableFunction(), [\Throwable::class]);
    }


    public function testCallWithNotSuitableExceptionType() {
        $backoff = new Backoff();
        $backoff->setInterval(2);
        $this->expectException(\Exception::class);
        $backoff->call($this->retryableFunction(), [RuntimeException::class]);
    }


    public function testRetry() {
        $backoff = new Backoff();
        $backoff->setInterval(2);

        $this->assertEquals('done', $backoff->call($this->retryableFunction(), [\Throwable::class]));
    }


//    public function testInterval() {
//        $backoff = new Backoff();
//        $backoff->setMaxAttempts(3);
//        $backoff->setInterval(2000);
//
//        $start = time();
//        $backoff->call($this->retryableFunction(), [\Throwable::class]);
//        $end = time();
//        $this->assertEquals(12, $end-$start);
//        $this->assertEquals('done', $backoff->call($this->retryableFunction(), [\Throwable::class]));
//    }


    protected function retryableFunction() {
        return function () {
            if ($this->calls < 3) {
                $this->calls++;
                throw new \Exception('Try again');
            }

            return 'done';
        };
    }

}